# Como Escrever Testes

Testes são funções Rust que verificam se o código não-teste está funcionando da maneira esperada. Os corpos das funções de teste normalmente executam estas três ações:

1.  Configuram os dados ou estados necessários.
2.  Executam o código que você deseja testar.
3.  Verificam se os resultados são o que você espera.

Vamos dar uma olhada nos recursos que o Rust fornece especificamente para escrever testes que realizam essas ações, que incluem o atributo `test`, algumas macros e o atributo `should_panic`.

### A Anatomia de uma Função de Teste

Na sua forma mais simples, um teste em Rust é uma função anotada com o atributo `test`. Atributos são metadados sobre pedaços de código Rust; um exemplo é o atributo `derive` que usamos com structs no Capítulo 5. Para transformar uma função em uma função de teste, adicione `#[test]` na linha antes de `fn`. Quando você executa seus testes com o comando `cargo test`, o Rust constrói um binário executor de testes que executa as funções anotadas e informa se cada função de teste passa ou falha.

Sempre que criamos um novo projeto de biblioteca com o Cargo, um módulo de teste com uma função de teste é gerado automaticamente para nós. Este módulo oferece um modelo para escrever seus testes, para que você não precise procurar a estrutura e a sintaxe exatas toda vez que iniciar um novo projeto. Você pode adicionar quantas funções de teste adicionais e quantos módulos de teste desejar!

Exploraremos alguns aspectos de como os testes funcionam experimentando o teste de modelo antes de realmente testarmos qualquer código. Em seguida, escreveremos alguns testes do mundo real que chamam algum código que escrevemos e verificaremos se seu comportamento está correto.

Vamos criar um novo projeto de biblioteca chamado `adder` que somará dois números:

```
$ cargo new adder --lib
     Created library `adder` project
$ cd adder
```

O conteúdo do arquivo *src/lib.rs* em sua biblioteca `adder` deve se parecer com a Listagem 11-1.

Nome do arquivo: src/lib.rs

```rust
pub fn add(left: u64, right: u64) -> u64 {
    left + right
}

#[cfg(test)]
mod tests {
    use super::*;

    #[test]
    fn it_works() {
        let result = add(2, 2);
        assert_eq!(result, 4);
    }
}
```
Listagem 11-1: O código gerado automaticamente por `cargo new`

O arquivo começa com uma função `add` de exemplo, para que tenhamos algo para testar.

Por enquanto, vamos nos concentrar apenas na função `it_works`. Observe a anotação `#[test]`: este atributo indica que esta é uma função de teste, para que o executor de testes saiba tratar esta função como um teste. Também podemos ter funções que não são de teste no módulo `tests` para ajudar a configurar cenários comuns ou executar operações comuns, então sempre precisamos indicar quais funções são testes.

O corpo da função de exemplo usa a macro `assert_eq!` para verificar se `result`, que contém o resultado da chamada de `add` com 2 e 2, é igual a 4. Essa verificação serve como um exemplo do formato para um teste típico. Vamos executá-lo para ver que este teste passa.

O comando `cargo test` executa todos os testes em nosso projeto, como mostrado na Listagem 11-2.

```
$ cargo test
   Compiling adder v0.1.0 (file:///projects/adder)
    Finished `test` profile [unoptimized + debuginfo] target(s) in 0.57s
     Running unittests src/lib.rs (file:///projects/adder/target/debug/deps/adder-7acb243c25ffd9dc)

running 1 test
test tests::it_works ... ok

test result: ok. 1 passed; 0 failed; 0 ignored; 0 measured; 0 filtered out; finished in 0.00s

   Doc-tests adder

running 0 tests

test result: ok. 0 passed; 0 failed; 0 ignored; 0 measured; 0 filtered out; finished in 0.00s
```
Listagem 11-2: A saída da execução do teste gerado automaticamente

O Cargo compilou e executou o teste. Vemos a linha `running 1 test`. A próxima linha mostra o nome da função de teste gerada, chamada `tests::it_works`, e que o resultado da execução desse teste é `ok`. O resumo geral `test result: ok.` significa que todos os testes passaram, e a parte que diz `1 passed; 0 failed` totaliza o número de testes que passaram ou falharam.

É possível marcar um teste como ignorado para que ele não seja executado em uma instância específica; abordaremos isso na seção "Ignorando Alguns Testes, a Menos que Especificamente Solicitados" mais adiante neste capítulo. Como não fizemos isso aqui, o resumo mostra `0 ignored`.

A estatística `0 measured` é para testes de benchmark que medem o desempenho. Os testes de benchmark estão, até o momento, disponíveis apenas no Rust nightly. Consulte a documentação sobre testes de benchmark para saber mais.

Podemos passar um argumento para o comando `cargo test` para executar apenas os testes cujo nome corresponda a uma string; isso é chamado de *filtragem* e abordaremos isso na seção "Executando um Subconjunto de Testes por Nome". Aqui, não filtramos os testes em execução, então o final do resumo mostra `0 filtered out`.

A próxima parte da saída do teste começando em `Doc-tests adder` é para os resultados de quaisquer testes de documentação. Ainda não temos nenhum teste de documentação, mas o Rust pode compilar quaisquer exemplos de código que apareçam em nossa documentação da API. Esse recurso ajuda a manter seus documentos e seu código em sincronia! Discutiremos como escrever testes de documentação na seção "Comentários de Documentação como Testes" do Capítulo 14. Por enquanto, ignoraremos a saída `Doc-tests`.

Vamos começar a personalizar o teste para nossas próprias necessidades. Primeiro, altere o nome da função `it_works` para um nome diferente, como `exploration`, assim:

Nome do arquivo: src/lib.rs

```rust
pub fn add(left: u64, right: u64) -> u64 {
    left + right
}

#[cfg(test)]
mod tests {
    use super::*;

    #[test]
    fn exploration() {
        let result = add(2, 2);
        assert_eq!(result, 4);
    }
}
```
Em seguida, execute `cargo test` novamente. A saída agora mostra `exploration` em vez de `it_works`:

```
$ cargo test
   Compiling adder v0.1.0 (file:///projects/adder)
    Finished `test` profile [unoptimized + debuginfo] target(s) in 0.59s
     Running unittests src/lib.rs (target/debug/deps/adder-92948b65e88960b4)

running 1 test
test tests::exploration ... ok

test result: ok. 1 passed; 0 failed; 0 ignored; 0 measured; 0 filtered out; finished in 0.00s

   Doc-tests adder

running 0 tests

test result: ok. 0 passed; 0 failed; 0 ignored; 0 measured; 0 filtered out; finished in 0.00s
```
Agora vamos adicionar outro teste, mas desta vez faremos um teste que falha! Os testes falham quando algo na função de teste entra em pânico. Cada teste é executado em uma nova thread, e quando a thread principal vê que uma thread de teste morreu, o teste é marcado como falhado. No Capítulo 9, falamos sobre como a maneira mais simples de entrar em pânico é chamar a macro `panic!`. Insira o novo teste como uma função chamada `another`, para que seu arquivo *src/lib.rs* se pareça com a Listagem 11-3.

Nome do arquivo: src/lib.rs

```rust
pub fn add(left: u64, right: u64) -> u64 {
    left + right
}

#[cfg(test)]
mod tests {
    use super::*;

    #[test]
    fn exploration() {
        let result = add(2, 2);
        assert_eq!(result, 4);
    }

    #[test]
    fn another() {
        panic!("Make this test fail"); //Faz esse teste falhar
    }
}
```
Listagem 11-3: Adicionando um segundo teste que falhará porque chamamos a macro `panic!`

Execute os testes novamente usando `cargo test`. A saída deve se parecer com a Listagem 11-4, que mostra que nosso teste `exploration` passou e `another` falhou.

```
$ cargo test
   Compiling adder v0.1.0 (file:///projects/adder)
    Finished `test` profile [unoptimized + debuginfo] target(s) in 0.72s
     Running unittests src/lib.rs (target/debug/deps/adder-92948b65e88960b4)

running 2 tests
test tests::another ... FAILED
test tests::exploration ... ok

failures:

---- tests::another stdout ----
thread 'tests::another' panicked at src/lib.rs:17:9:
Make this test fail
note: run with `RUST_BACKTRACE=1` environment variable to display a backtrace

failures:
    tests::another

test result: FAILED. 1 passed; 1 failed; 0 ignored; 0 measured; 0 filtered out; finished in 0.00s

error: test failed, to rerun pass `--lib`
```
Listagem 11-4: Resultados do teste quando um teste passa e um teste falha

Em vez de `ok`, a linha `test tests::another` mostra `FAILED`. Duas novas seções aparecem entre os resultados individuais e o resumo: a primeira exibe o motivo detalhado de cada falha no teste. Neste caso, obtemos os detalhes de que `another` falhou porque entrou em `panicked at 'Make this test fail'` na linha 17 no arquivo *src/lib.rs*. A próxima seção lista apenas os nomes de todos os testes com falha, o que é útil quando há muitos testes e muitas saídas detalhadas de testes com falha. Podemos usar o nome de um teste com falha para executar apenas esse teste para depurá-lo mais facilmente; falaremos mais sobre maneiras de executar testes na seção "Controlando como os testes são executados".

A linha de resumo é exibida no final: no geral, nosso resultado do teste é `FAILED`. Tivemos um teste aprovado e um teste reprovado.

Agora que você viu como são os resultados dos testes em diferentes cenários, vamos dar uma olhada em algumas macros além de `panic!` que são úteis em testes.

### Verificando Resultados com a Macro `assert!`

A macro `assert!`, fornecida pela biblioteca padrão, é útil quando você deseja garantir que alguma condição em um teste seja avaliada como `true`. Fornecemos à macro `assert!` um argumento que é avaliado como um booleano. Se o valor for `true`, nada acontece e o teste passa. Se o valor for `false`, a macro `assert!` chama `panic!` para fazer o teste falhar. Usar a macro `assert!` nos ajuda a verificar se nosso código está funcionando da maneira que pretendemos.

No Capítulo 5, Listagem 5-15, usamos uma struct `Rectangle` e um método `can_hold`, que são repetidos aqui na Listagem 11-5. Vamos colocar este código no arquivo *src/lib.rs* e, em seguida, escrever alguns testes para ele usando a macro `assert!`.

Nome do arquivo: src/lib.rs

```rust
#[derive(Debug)]
struct Rectangle {
    width: u32,
    height: u32,
}

impl Rectangle {
    fn can_hold(&self, other: &Rectangle) -> bool {
        self.width > other.width && self.height > other.height
    }
}
```
Listagem 11-5: A struct `Rectangle` e seu método `can_hold` do Capítulo 5

O método `can_hold` retorna um booleano, o que significa que é um caso de uso perfeito para a macro `assert!`. Na Listagem 11-6, escrevemos um teste que exercita o método `can_hold` criando uma instância `Rectangle` que tem uma largura de 8 e uma altura de 7 e verificando se ela pode conter outra instância `Rectangle` que tem uma largura de 5 e uma altura de 1.

Nome do arquivo: src/lib.rs

```rust
#[derive(Debug)]
struct Rectangle {
    width: u32,
    height: u32,
}

impl Rectangle {
    fn can_hold(&self, other: &Rectangle) -> bool {
        self.width > other.width && self.height > other.height
    }
}

#[cfg(test)]
mod tests {
    use super::*;

    #[test]
    fn larger_can_hold_smaller() {
        let larger = Rectangle {
            width: 8,
            height: 7,
        };
        let smaller = Rectangle {
            width: 5,
            height: 1,
        };

        assert!(larger.can_hold(&smaller));
    }
}
```
Listagem 11-6: Um teste para `can_hold` que verifica se um retângulo maior pode realmente conter um retângulo menor

Observe a linha `use super::*;` dentro do módulo `tests`. O módulo `tests` é um módulo regular que segue as regras usuais de visibilidade que abordamos no Capítulo 7 na seção "Caminhos para Referir-se a um Item na Árvore de Módulos". Como o módulo `tests` é um módulo interno, precisamos trazer o código em teste no módulo externo para o escopo do módulo interno. Usamos um glob aqui, para que qualquer coisa que definirmos no módulo externo esteja disponível para este módulo `tests`.

Nomeamos nosso teste como `larger_can_hold_smaller` e criamos as duas instâncias `Rectangle` de que precisamos. Em seguida, chamamos a macro `assert!` e passamos a ela o resultado da chamada de `larger.can_hold(&smaller)`. Essa expressão deve retornar `true`, então nosso teste deve passar. Vamos descobrir!

```
$ cargo test
   Compiling rectangle v0.1.0 (file:///projects/rectangle)
    Finished `test` profile [unoptimized + debuginfo] target(s) in 0.66s
     Running unittests src/lib.rs (target/debug/deps/rectangle-6584c4561e48942e)

running 1 test
test tests::larger_can_hold_smaller ... ok

test result: ok. 1 passed; 0 failed; 0 ignored; 0 measured; 0 filtered out; finished in 0.00s

   Doc-tests rectangle

running 0 tests

test result: ok. 0 passed; 0 failed; 0 ignored; 0 measured; 0 filtered out; finished in 0.00s
```

Ele passa! Vamos adicionar outro teste, desta vez verificando se um retângulo menor não pode conter um retângulo maior:

Nome do arquivo: src/lib.rs

```rust
#[derive(Debug)]
struct Rectangle {
    width: u32,
    height: u32,
}

impl Rectangle {
    fn can_hold(&self, other: &Rectangle) -> bool {
        self.width > other.width && self.height > other.height
    }
}

#[cfg(test)]
mod tests {
    use super::*;

    #[test]
    fn larger_can_hold_smaller() {
        // --snip--
        let larger = Rectangle {
            width: 8,
            height: 7,
        };
        let smaller = Rectangle {
            width: 5,
            height: 1,
        };

        assert!(larger.can_hold(&smaller));
    }

    #[test]
    fn smaller_cannot_hold_larger() {
        let larger = Rectangle {
            width: 8,
            height: 7,
        };
        let smaller = Rectangle {
            width: 5,
            height: 1,
        };

        assert!(!smaller.can_hold(&larger));
    }
}
```

Como o resultado correto da função `can_hold` neste caso é `false`, precisamos negar esse resultado antes de passá-lo para a macro `assert!`. Como resultado, nosso teste passará se `can_hold` retornar `false`:

```
$ cargo test
   Compiling rectangle v0.1.0 (file:///projects/rectangle)
    Finished `test` profile [unoptimized + debuginfo] target(s) in 0.66s
     Running unittests src/lib.rs (target/debug/deps/rectangle-6584c4561e48942e)

running 2 tests
test tests::larger_can_hold_smaller ... ok
test tests::smaller_cannot_hold_larger ... ok

test result: ok. 2 passed; 0 failed; 0 ignored; 0 measured; 0 filtered out; finished in 0.00s

   Doc-tests rectangle

running 0 tests

test result: ok. 0 passed; 0 failed; 0 ignored; 0 measured; 0 filtered out; finished in 0.00s
```

Dois testes que passam! Agora vamos ver o que acontece com nossos resultados de teste quando introduzimos um bug em nosso código. Vamos alterar a implementação do método `can_hold` substituindo o sinal de maior que por um sinal de menor que quando ele compara as larguras:

```rust
#[derive(Debug)]
struct Rectangle {
    width: u32,
    height: u32,
}

// --snip--
impl Rectangle {
    fn can_hold(&self, other: &Rectangle) -> bool {
        self.width < other.width && self.height > other.height // Aqui trocamos > por <
    }
}

#[cfg(test)]
mod tests {
    use super::*;

    #[test]
    fn larger_can_hold_smaller() {
        let larger = Rectangle {
            width: 8,
            height: 7,
        };
        let smaller = Rectangle {
            width: 5,
            height: 1,
        };

        assert!(larger.can_hold(&smaller));
    }

    #[test]
    fn smaller_cannot_hold_larger() {
        let larger = Rectangle {
            width: 8,
            height: 7,
        };
        let smaller = Rectangle {
            width: 5,
            height: 1,
        };

        assert!(!smaller.can_hold(&larger));
    }
}
```

Executar os testes agora produz o seguinte:

```
$ cargo test
   Compiling rectangle v0.1.0 (file:///projects/rectangle)
    Finished `test` profile [unoptimized + debuginfo] target(s) in 0.66s
     Running unittests src/lib.rs (target/debug/deps/rectangle-6584c4561e48942e)

running 2 tests
test tests::larger_can_hold_smaller ... FAILED
test tests::smaller_cannot_hold_larger ... ok

failures:

---- tests::larger_can_hold_smaller stdout ----
thread 'tests::larger_can_hold_smaller' panicked at src/lib.rs:28:9:
assertion failed: larger.can_hold(&smaller)
note: run with `RUST_BACKTRACE=1` environment variable to display a backtrace

failures:
    tests::larger_can_hold_smaller

test result: FAILED. 1 passed; 1 failed; 0 ignored; 0 measured; 0 filtered out; finished in 0.00s

error: test failed, to rerun pass `--lib`
```

Nossos testes detectaram o bug! Como `larger.width` é `8` e `smaller.width` é `5`, a comparação das larguras em `can_hold` agora retorna `false`: 8 não é menor que 5.

### Testando Igualdade com as Macros `assert_eq!` e `assert_ne!`

Uma maneira comum de verificar a funcionalidade é testar a igualdade entre o resultado do código em teste e o valor que você espera que o código retorne. Você pode fazer isso usando a macro `assert!` e passando a ela uma expressão usando o operador `==`. No entanto, este é um teste tão comum que a biblioteca padrão fornece um par de macros — `assert_eq!` e `assert_ne!` — para realizar este teste de forma mais conveniente. Essas macros comparam dois argumentos quanto à igualdade ou desigualdade, respectivamente. Elas também imprimirão os dois valores se a verificação falhar, o que torna mais fácil ver *por que* o teste falhou; inversamente, a macro `assert!` indica apenas que obteve um valor `false` para a expressão `==`, sem imprimir os valores que levaram ao valor `false`.

Na Listagem 11-7, escrevemos uma função chamada `add_two` que adiciona `2` ao seu parâmetro e, em seguida, testamos essa função usando a macro `assert_eq!`.

Nome do arquivo: src/lib.rs

```rust
pub fn add_two(a: usize) -> usize {
    a + 2
}

#[cfg(test)]
mod tests {
    use super::*;

    #[test]
    fn it_adds_two() {
        let result = add_two(2);
        assert_eq!(result, 4);
    }
}
```
Listagem 11-7: Testando a função `add_two` usando a macro `assert_eq!`

Vamos verificar se ele passa!

```rust
$ cargo test
   Compiling adder v0.1.0 (file:///projects/adder)
    Finished `test` profile [unoptimized + debuginfo] target(s) in 0.58s
     Running unittests src/lib.rs (target/debug/deps/adder-92948b65e88960b4)

running 1 test
test tests::it_adds_two ... ok

test result: ok. 1 passed; 0 failed; 0 ignored; 0 measured; 0 filtered out; finished in 0.00s

   Doc-tests adder

running 0 tests

test result: ok. 0 passed; 0 failed; 0 ignored; 0 measured; 0 filtered out; finished in 0.00s
```
Criamos uma variável chamada `result` que contém o resultado da chamada de `add_two(2)`. Em seguida, passamos `result` e `4` como os argumentos para `assert_eq!`. A linha de saída para este teste é `test tests::it_adds_two ... ok`, e o texto `ok` indica que nosso teste passou!

Vamos introduzir um bug em nosso código para ver como é `assert_eq!` quando falha. Altere a implementação da função `add_two` para adicionar `3`:

```rust
pub fn add_two(a: usize) -> usize {
    a + 3 //Mudamos de 2 para 3
}

#[cfg(test)]
mod tests {
    use super::*;

    #[test]
    fn it_adds_two() {
        let result = add_two(2);
        assert_eq!(result, 4);
    }
}
```
Execute os testes novamente:

```rust
$ cargo test
   Compiling adder v0.1.0 (file:///projects/adder)
    Finished `test` profile [unoptimized + debuginfo] target(s) in 0.61s
     Running unittests src/lib.rs (target/debug/deps/adder-92948b65e88960b4)

running 1 test
test tests::it_adds_two ... FAILED

failures:

---- tests::it_adds_two stdout ----
thread 'tests::it_adds_two' panicked at src/lib.rs:12:9:
assertion `left == right` failed
  left: 5
 right: 4
note: run with `RUST_BACKTRACE=1` environment variable to display a backtrace

failures:
    tests::it_adds_two

test result: FAILED. 0 passed; 1 failed; 0 ignored; 0 measured; 0 filtered out; finished in 0.00s

error: test failed, to rerun pass `--lib`
```

Nosso teste detectou o bug! O teste `it_adds_two` falhou, e a mensagem nos diz que `assertion `left == right` failed` e quais são os valores de `left` e `right`. Esta mensagem nos ajuda a começar a depurar: o argumento `left`, onde tínhamos o resultado da chamada de `add_two(2)`, era `5`, mas o argumento `right` era `4`. Você pode imaginar que isso seria especialmente útil quando tivermos muitos testes em andamento.

Observe que, em algumas linguagens e frameworks de teste, os parâmetros para funções de verificação de igualdade são chamados de `expected` e `actual`, e a ordem em que especificamos os argumentos é importante. No entanto, em Rust, eles são chamados de `left` e `right`, e a ordem em que especificamos o valor que esperamos e o valor que o código produz não importa. Poderíamos escrever a verificação neste teste como `assert_eq!(4, result)`, o que produziria a mesma mensagem de falha que exibe `assertion failed: `(left == right)``.

A macro `assert_ne!` passará se os dois valores que fornecermos a ela não forem iguais e falhará se forem iguais. Essa macro é mais útil para casos em que não temos certeza de qual *será* um valor, mas sabemos qual o valor definitivamente *não deveria* ser. Por exemplo, se estivermos testando uma função que tem a garantia de alterar sua entrada de alguma forma, mas a maneira como a entrada é alterada depende do dia da semana em que executamos nossos testes, a melhor coisa a verificar pode ser que a saída da função não é igual à entrada.

Nos bastidores, as macros `assert_eq!` e `assert_ne!` usam os operadores `==` e `!=`, respectivamente. Quando as verificações falham, essas macros imprimem seus argumentos usando a formatação de depuração, o que significa que os valores que estão sendo comparados devem implementar as traits `PartialEq` e `Debug`. Todos os tipos primitivos e a maioria dos tipos da biblioteca padrão implementam essas traits. Para structs e enums que você definir, você precisará implementar `PartialEq` para verificar a igualdade desses tipos. Você também precisará implementar `Debug` para imprimir os valores quando a verificação falhar. Como ambas as traits são traits deriváveis, conforme mencionado na Listagem 5-12 no Capítulo 5, isso geralmente é tão simples quanto adicionar a anotação `#[derive(PartialEq, Debug)]` à sua definição de struct ou enum. Consulte o Apêndice C, "Traits Deriváveis", para obter mais detalhes sobre essas e outras traits deriváveis.

### Adicionando Mensagens de Falha Personalizadas

Você também pode adicionar uma mensagem personalizada a ser impressa com a mensagem de falha como argumentos opcionais para as macros `assert!`, `assert_eq!` e `assert_ne!`. Quaisquer argumentos especificados após os argumentos necessários são passados para a macro `format!` (discutida no Capítulo 8 na seção "Concatenação com o Operador `+` ou a Macro `format!`"), para que você possa passar uma string de formato que contenha espaços reservados `{}` e valores para inserir nesses espaços reservados. Mensagens personalizadas são úteis para documentar o que uma verificação significa; quando um teste falha, você terá uma ideia melhor de qual é o problema com o código.

Por exemplo, digamos que temos uma função que cumprimenta as pessoas pelo nome e queremos testar se o nome que passamos para a função aparece na saída:

Nome do arquivo: src/lib.rs

```rust
pub fn greeting(name: &str) -> String {
    format!("Hello {name}!")
}

#[cfg(test)]
mod tests {
    use super::*;

    #[test]
    fn greeting_contains_name() {
        let result = greeting("Carol");
        assert!(result.contains("Carol"));
    }
}
```

Os requisitos para este programa ainda não foram acordados, e temos certeza de que o texto `Hello` no início da saudação será alterado. Decidimos que não queremos ter que atualizar o teste quando os requisitos mudarem, então, em vez de verificar a igualdade exata com o valor retornado da função `greeting`, vamos apenas verificar se a saída contém o texto do parâmetro de entrada.

Agora vamos introduzir um bug neste código alterando `greeting` para excluir `name` para ver como é a falha de teste padrão:

```rust
pub fn greeting(name: &str) -> String {
    String::from("Hello!") // Removemos o {name}
}

#[cfg(test)]
mod tests {
    use super::*;

    #[test]
    fn greeting_contains_name() {
        let result = greeting("Carol");
        assert!(result.contains("Carol"));
    }
}
```
Executar este teste produz o seguinte:

```rust
$ cargo test
   Compiling greeter v0.1.0 (file:///projects/greeter)
    Finished `test` profile [unoptimized + debuginfo] target(s) in 0.91s
     Running unittests src/lib.rs (target/debug/deps/greeter-170b942eb5bf5e3a)

running 1 test
test tests::greeting_contains_name ... FAILED

failures:

---- tests::greeting_contains_name stdout ----
thread 'tests::greeting_contains_name' panicked at src/lib.rs:12:9:
assertion failed: result.contains("Carol")
note: run with `RUST_BACKTRACE=1` environment variable to display a backtrace

failures:
    tests::greeting_contains_name

test result: FAILED. 0 passed; 1 failed; 0 ignored; 0 measured; 0 filtered out; finished in 0.00s

error: test failed, to rerun pass `--lib`
```

Este resultado indica apenas que a verificação falhou e em qual linha a verificação está. Uma mensagem de falha mais útil imprimiria o valor da função `greeting`. Vamos adicionar uma mensagem de falha personalizada composta por uma string de formato com um espaço reservado preenchido com o valor real que obtivemos da função `greeting`:

```rust
pub fn greeting(name: &str) -> String {
    String::from("Hello!")
}

#[cfg(test)]
mod tests {
    use super::*;

    #[test]
    fn greeting_contains_name() {
        let result = greeting("Carol");
        assert!(
            result.contains("Carol"),
            "Greeting did not contain name, value was `{result}`" //Mensagem de erro personalizada
        );
    }
}
```
Agora, quando executarmos o teste, obteremos uma mensagem de erro mais informativa:

```rust
$ cargo test
   Compiling greeter v0.1.0 (file:///projects/greeter)
    Finished `test` profile [unoptimized + debuginfo] target(s) in 0.93s
     Running unittests src/lib.rs (target/debug/deps/greeter-170b942eb5bf5e3a)

running 1 test
test tests::greeting_contains_name ... FAILED

failures:

---- tests::greeting_contains_name stdout ----
thread 'tests::greeting_contains_name' panicked at src/lib.rs:12:9:
Greeting did not contain name, value was `Hello!`
note: run with `RUST_BACKTRACE=1` environment variable to display a backtrace

failures:
    tests::greeting_contains_name

test result: FAILED. 0 passed; 1 failed; 0 ignored; 0 measured; 0 filtered out; finished in 0.00s

error: test failed, to rerun pass `--lib`
```

Podemos ver o valor que realmente obtivemos na saída do teste, o que nos ajudaria a depurar o que aconteceu em vez do que esperávamos que acontecesse.

### Verificando Pânicos com `should_panic`

Além de verificar os valores de retorno, é importante verificar se nosso código lida com as condições de erro como esperamos. Por exemplo, considere o tipo `Guess` que criamos no Capítulo 9, Listagem 9-13. Outro código que usa `Guess` depende da garantia de que as instâncias `Guess` conterão apenas valores entre 1 e 100. Podemos escrever um teste que garanta que a tentativa de criar uma instância `Guess` com um valor fora desse intervalo entre em pânico.

Fazemos isso adicionando o atributo `should_panic` à nossa função de teste. O teste passa se o código dentro da função entrar em pânico; o teste falha se o código dentro da função não entrar em pânico.

A Listagem 11-8 mostra um teste que verifica se as condições de erro de `Guess::new` acontecem quando esperamos que aconteçam.

Nome do arquivo: src/lib.rs

```rust
pub struct Guess {
    value: i32,
}

impl Guess {
    pub fn new(value: i32) -> Guess {
        if value < 1 || value > 100 {
            panic!("Guess value must be between 1 and 100, got {value}.");
        }

        Guess { value }
    }
}

#[cfg(test)]
mod tests {
    use super::*;

    #[test]
    #[should_panic]
    fn greater_than_100() {
        Guess::new(200);
    }
}
```
Listagem 11-8: Testando se uma condição causará um `panic!`

Colocamos o atributo `#[should_panic]` após o atributo `#[test]` e antes da função de teste à qual ele se aplica. Vamos dar uma olhada no resultado quando este teste passar:

```rust
$ cargo test
   Compiling guessing_game v0.1.0 (file:///projects/guessing_game)
    Finished `test` profile [unoptimized + debuginfo] target(s) in 0.58s
     Running unittests src/lib.rs (target/debug/deps/guessing_game-57d70c3acb738f4d)

running 1 test
test tests::greater_than_100 - should panic ... ok

test result: ok. 1 passed; 0 failed; 0 ignored; 0 measured; 0 filtered out; finished in 0.00s

   Doc-tests guessing_game

running 0 tests

test result: ok. 0 passed; 0 failed; 0 ignored; 0 measured; 0 filtered out; finished in 0.00s
```
Parece bom! Agora vamos introduzir um bug em nosso código removendo a condição de que a função `new` entrará em pânico se o valor for maior que 100:
```rust
pub struct Guess {
    value: i32,
}

// --snip--
impl Guess {
    pub fn new(value: i32) -> Guess {
        if value < 1 {
            panic!("Guess value must be between 1 and 100, got {value}.");
        }

        Guess { value }
    }
}

#[cfg(test)]
mod tests {
    use super::*;

    #[test]
    #[should_panic]
    fn greater_than_100() {
        Guess::new(200);
    }
}
```

Quando executarmos o teste na Listagem 11-8, ele falhará:

```
$ cargo test
   Compiling guessing_game v0.1.0 (file:///projects/guessing_game)
    Finished `test` profile [unoptimized + debuginfo] target(s) in 0.62s
     Running unittests src/lib.rs (target/debug/deps/guessing_game-57d70c3acb738f4d)

running 1 test
test tests::greater_than_100 - should panic ... FAILED

failures:

---- tests::greater_than_100 stdout ----
note: test did not panic as expected

failures:
    tests::greater_than_100

test result: FAILED. 0 passed; 1 failed; 0 ignored; 0 measured; 0 filtered out; finished in 0.00s

error: test failed, to rerun pass `--lib`
```

Não recebemos uma mensagem muito útil neste caso, mas quando olhamos para a função de teste, vemos que ela está anotada com `#[should_panic]`. A falha que obtivemos significa que o código na função de teste não causou um pânico.

Testes que usam `should_panic` podem ser imprecisos. Um teste `should_panic` passaria mesmo que o teste entre em pânico por um motivo diferente daquele que esperávamos. Para tornar os testes `should_panic` mais precisos, podemos adicionar um parâmetro `expected` opcional ao atributo `should_panic`. O executor de testes garantirá que a mensagem de falha contenha o texto fornecido. Por exemplo, considere o código modificado para `Guess` na Listagem 11-9, onde a função `new` entra em pânico com mensagens diferentes dependendo se o valor é muito pequeno ou muito grande.

Nome do arquivo: src/lib.rs

```rust
pub struct Guess {
    value: i32,
}

// --snip--

impl Guess {
    pub fn new(value: i32) -> Guess {
        if value < 1 {
            panic!(
                "Guess value must be greater than or equal to 1, got {value}."
            );
        } else if value > 100 {
            panic!(
                "Guess value must be less than or equal to 100, got {value}."
            );
        }

        Guess { value }
    }
}

#[cfg(test)]
mod tests {
    use super::*;

    #[test]
    #[should_panic(expected = "less than or equal to 100")]
    fn greater_than_100() {
        Guess::new(200);
    }
}
```
Listagem 11-9: Testando um `panic!` com uma mensagem de pânico contendo uma substring especificada

Este teste passará porque o valor que colocamos no parâmetro `expected` do atributo `should_panic` é uma substring da mensagem com a qual a função `Guess::new` entra em pânico. Poderíamos ter especificado toda a mensagem de pânico que esperamos, que neste caso seria `Guess value must be less than or equal to 100, got 200.`. O que você escolhe especificar depende de quanto da mensagem de pânico é única ou dinâmica e de quão preciso você deseja que seu teste seja. Neste caso, uma substring da mensagem de pânico é suficiente para garantir que o código na função de teste execute o caso `else if value > 100`.

Para ver o que acontece quando um teste `should_panic` com uma mensagem `expected` falha, vamos novamente introduzir um bug em nosso código trocando os corpos dos blocos `if value < 1` e `else if value > 100`:

```rust
pub struct Guess {
    value: i32,
}

impl Guess {
    pub fn new(value: i32) -> Guess {
        if value < 1 {
            panic!(
                "Guess value must be less than or equal to 100, got {value}."
            );
        } else if value > 100 {
            panic!(
                "Guess value must be greater than or equal to 1, got {value}."
            );
        }

        Guess { value }
    }
}

#[cfg(test)]
mod tests {
    use super::*;

    #[test]
    #[should_panic(expected = "less than or equal to 100")]
    fn greater_than_100() {
        Guess::new(200);
    }
}
```

Desta vez, quando executarmos o teste `should_panic`, ele falhará:

```rust
$ cargo test
   Compiling guessing_game v0.1.0 (file:///projects/guessing_game)
    Finished `test` profile [unoptimized + debuginfo] target(s) in 0.66s
     Running unittests src/lib.rs (target/debug/deps/guessing_game-57d70c3acb738f4d)

running 1 test
test tests::greater_than_100 - should panic ... FAILED

failures:

---- tests::greater_than_100 stdout ----
thread 'tests::greater_than_100' panicked at src/lib.rs:12:13:
Guess value must be greater than or equal to 1, got 200.
note: run with `RUST_BACKTRACE=1` environment variable to display a backtrace
note: panic did not contain expected string
      panic message: `"Guess value must be greater than or equal to 1, got 200."`,
 expected substring: `"less than or equal to 100"`

failures:
    tests::greater_than_100

test result: FAILED. 0 passed; 1 failed; 0 ignored; 0 measured; 0 filtered out; finished in 0.00s

error: test failed, to rerun pass `--lib`
```

A mensagem de falha indica que este teste realmente entrou em pânico como esperávamos, mas a mensagem de pânico não incluiu a string esperada `less than or equal to 100`. A mensagem de pânico que obtivemos neste caso foi `Guess value must be greater than or equal to 1, got 200.`. Agora podemos começar a descobrir onde está nosso bug!

### Usando `Result<T, E>` em Testes

Nossos testes até agora todos entram em pânico quando falham. Também podemos escrever testes que usam `Result<T, E>`! Aqui está o teste da Listagem 11-1, reescrito para usar `Result<T, E>` e retornar um `Err` em vez de entrar em pânico:

```rust
pub fn add(left: u64, right: u64) -> u64 {
    left + right
}

#[cfg(test)]
mod tests {
    use super::*;

    #[test]
    fn it_works() -> Result<(), String> {
        let result = add(2, 2);

        if result == 4 {
            Ok(())
        } else {
            Err(String::from("two plus two does not equal four")) //dois mais dois não é igual a quatro
        }
    }
}
```

A função `it_works` agora tem o tipo de retorno `Result<(), String>`. No corpo da função, em vez de chamar a macro `assert_eq!`, retornamos `Ok(())` quando o teste passa e um `Err` com uma `String` dentro quando o teste falha.

Escrever testes para que eles retornem um `Result<T, E>` permite que você use o operador ponto de interrogação no corpo dos testes, o que pode ser uma maneira conveniente de escrever testes que devem falhar se alguma operação dentro deles retornar uma variante `Err`.

Você não pode usar a anotação `#[should_panic]` em testes que usam `Result<T, E>`. Para verificar se uma operação retorna uma variante `Err`, *não* use o operador ponto de interrogação no valor `Result<T, E>`. Em vez disso, use `assert!(value.is_err())`.

Agora que você conhece várias maneiras de escrever testes, vamos dar uma olhada no que está acontecendo quando executamos nossos testes e explorar as diferentes opções que podemos usar com `cargo test`.
